#VRML_SIM R2022a utf8
WorldInfo {
  info [
    "A simple RCJ Soccer game simulated using Webots."
  ]
  title "RCJ Soccer Sim"
  optimalThreadCount 8
}
Viewpoint {
  orientation -0.5980258967674501 0.5695602523497129 0.5638848692231582 2.155913289465122
  position 3.1525164800442214e-06 3.1525253944055953e-06 4.036409005064675
}
TexturedBackground {
}
TexturedBackgroundLight {
}
DEF SOCCER_FIELD Solid {
  children [
    DEF GROUND Transform {
      rotation 0 0 1 1.5707996938995747
      children [
        Shape {
          appearance PBRAppearance {
            baseColorMap ImageTexture {
              url [
                "soccer/soccer-256.jpg"
              ]
            }
            roughness 1
            metalness 0
          }
          geometry Plane {
            size 1.5 1.5
          }
        }
      ]
    }
    DEF YELLOW_GOAL_GROUND Shape {
      appearance PBRAppearance {
        baseColorMap ImageTexture {
          url [
            "soccer/soccer-256.jpg"
          ]
        }
        roughness 1
        metalness 0
      }
      geometry IndexedFaceSet {
        coord Coordinate {
          point [
            -0.75 -0.95 0
            -0.75 -0.75 0
            0.75 -0.75 0
            0.75 -0.95 0
          ]
        }
        texCoord TextureCoordinate {
          point [
            0 0
            0 0
            0 0
            0 0
          ]
        }
        ccw FALSE
        coordIndex [
          0, 1, 2, 3
        ]
        texCoordIndex [
          0, 1, 2, 3
        ]
      }
    }
    DEF BLUE_GOAL_GROUND Shape {
      appearance PBRAppearance {
        baseColorMap ImageTexture {
          url [
            "soccer/soccer-256.jpg"
          ]
        }
        roughness 1
        metalness 0
      }
      geometry IndexedFaceSet {
        coord Coordinate {
          point [
            -0.75 0.95 0
            -0.75 0.75 0
            0.75 0.75 0
            0.75 0.95 0
          ]
        }
        texCoord TextureCoordinate {
          point [
            0 0
            0 0
            0 0
            0 0
          ]
        }
        coordIndex [
          0, 1, 2, 3
        ]
        texCoordIndex [
          0, 1, 2, 3
        ]
      }
    }
    DEF NORTH_WALL Shape {
      appearance DEF WALL_APPEARANCE PBRAppearance {
        baseColor 0.388235 0.388235 0.388235
        roughness 1
        metalness 0
      }
      geometry IndexedFaceSet {
        coord Coordinate {
          point [
            -0.66 -0.76 0
            -0.21 -0.76 0
            -0.21 -0.75 0
            -0.59 -0.75 0
            -0.65 -0.69 0
            -0.65 0.69 0
            -0.59 0.75 0
            -0.21 0.75 0
            -0.21 0.76 0
            -0.65 0.76 0
            -0.66 0.76 0
            -0.66 -0.76 0.09
            -0.21 -0.76 0.09
            -0.21 -0.75 0.09
            -0.59 -0.75 0.09
            -0.65 -0.69 0.09
            -0.65 0.69 0.09
            -0.59 0.75 0.09
            -0.21 0.75 0.09
            -0.21 0.76 0.09
            -0.65 0.76 0.09
            -0.66 0.76 0.09
          ]
        }
        coordIndex [
          0, 10, 9, -1, 9, 8, 7, -1, 9, 7, 6, -1, 2, 1, 0, -1, 3, 2, 0, -1, 9, 6, 5, -1, 4, 3, 0, -1, 0, 9, 5, -1, 0, 5, 4, -1, 11, 12, 13, -1, 11, 13, 14, -1, 20, 21, 11, -1, 18, 19, 20, -1, 17, 18, 20, -1, 11, 14, 15, -1, 16, 17, 20, -1, 11, 15, 16, -1, 11, 16, 20, -1, 0, 1, 12, 11, -1, 1, 2, 13, 12, -1, 2, 3, 14, 13, -1, 3, 4, 15, 14, -1, 4, 5, 16, 15, -1, 5, 6, 17, 16, -1, 6, 7, 18, 17, -1, 7, 8, 19, 18, -1, 8, 9, 20, 19, -1, 9, 10, 21, 20, -1, 10, 0, 11, 21, -1
        ]
      }
    }
    DEF SOUTH_WALL Shape {
      appearance USE WALL_APPEARANCE
      geometry IndexedFaceSet {
        coord Coordinate {
          point [
            0.66 -0.76 0
            0.66 0.76 0
            0.65 0.76 0
            0.21 0.76 0
            0.21 0.75 0
            0.59 0.75 0
            0.65 0.69 0
            0.65 -0.69 0
            0.59 -0.75 0
            0.21 -0.75 0
            0.21 -0.76 0
            0.66 -0.76 0.09
            0.66 0.76 0.09
            0.65 0.76 0.09
            0.21 0.76 0.09
            0.21 0.75 0.09
            0.59 0.75 0.09
            0.65 0.69 0.09
            0.65 -0.69 0.09
            0.59 -0.75 0.09
            0.21 -0.75 0.09
            0.21 -0.76 0.09
          ]
        }
        coordIndex [
          0, 10, 9, -1, 0, 9, 8, -1, 2, 1, 0, -1, 4, 3, 2, -1, 5, 4, 2, -1, 0, 8, 7, -1, 6, 5, 2, -1, 0, 7, 6, -1, 0, 6, 2, -1, 11, 12, 13, -1, 13, 14, 15, -1, 13, 15, 16, -1, 20, 21, 11, -1, 19, 20, 11, -1, 13, 16, 17, -1, 18, 19, 11, -1, 11, 13, 17, -1, 11, 17, 18, -1, 0, 1, 12, 11, -1, 1, 2, 13, 12, -1, 2, 3, 14, 13, -1, 3, 4, 15, 14, -1, 4, 5, 16, 15, -1, 5, 6, 17, 16, -1, 6, 7, 18, 17, -1, 7, 8, 19, 18, -1, 8, 9, 20, 19, -1, 9, 10, 21, 20, -1, 10, 0, 11, 21, -1
        ]
      }
    }
    DEF YELLOW_GOAL Shape {
      appearance PBRAppearance {
        baseColor 1 1 0
        roughness 1
        metalness 0
      }
      geometry IndexedFaceSet {
        coord Coordinate {
          point [
            -0.21 -0.86 0
            0.21 -0.86 0
            0.21 -0.75 0
            0.2 -0.75 0
            0.2 -0.85 0
            -0.2 -0.85 0
            -0.2 -0.75 0
            -0.21 -0.75 0
            -0.21 -0.86 0
            -0.21 -0.86 0.12
            0.21 -0.86 0.12
            0.21 -0.75 0.12
            0.2 -0.75 0.12
            0.2 -0.85 0.12
            -0.2 -0.85 0.12
            -0.2 -0.75 0.12
            -0.21 -0.75 0.12
            -0.21 -0.86 0.12
          ]
        }
        coordIndex [
          0, 1, 2, 3, 4, 5, 6, 7, 8, -1, 0, 1, 10, 9, -1, 1, 2, 11, 10, -1, 2, 3, 12, 11, -1, 3, 4, 13, 12, -1, 4, 5, 14, 13, -1, 5, 6, 15, 14, -1, 6, 7, 16, 15, -1, 7, 8, 17, 16, -1
        ]
      }
    }
    DEF BLUE_GOAL Shape {
      appearance PBRAppearance {
        baseColor 0 0 1
        roughness 1
        metalness 0
      }
      geometry IndexedFaceSet {
        coord Coordinate {
          point [
            -0.21 0.86 0
            -0.21 0.75 0
            -0.2 0.75 0
            -0.2 0.85 0
            0.2 0.85 0
            0.2 0.75 0
            0.21 0.75 0
            0.21 0.86 0
            -0.21 0.86 0
            -0.21 0.86 0.12
            -0.21 0.75 0.12
            -0.2 0.75 0.12
            -0.2 0.85 0.12
            0.2 0.85 0.12
            0.2 0.75 0.12
            0.21 0.75 0.12
            0.21 0.86 0.12
            -0.21 0.86 0.12
          ]
        }
        coordIndex [
          0, 1, 2, 3, 4, 5, 6, 7, 8, -1, 0, 1, 10, 9, -1, 1, 2, 11, 10, -1, 2, 3, 12, 11, -1, 3, 4, 13, 12, -1, 4, 5, 14, 13, -1, 5, 6, 15, 14, -1, 6, 7, 16, 15, -1, 7, 8, 17, 16, -1
        ]
      }
    }
  ]
  name "soccer field"
  boundingObject Group {
    children [
      USE GROUND
      DEF NOTH_BBOX Transform {
        translation 0.655 0 0.045
        children [
          Box {
            size 0.01 1.5 0.09
          }
        ]
      }
      DEF SOUTH_BBOX Transform {
        translation -0.655 0 0.045
        children [
          Box {
            size 0.01 1.5 0.09
          }
        ]
      }
      DEF NW_BBOX Transform {
        translation 0.43 0.755 0.045
        children [
          Box {
            size 0.435 0.01 0.09
          }
        ]
      }
      DEF NE_BBOX Transform {
        translation 0.43 -0.755 0.045
        children [
          Box {
            size 0.435 0.01 0.09
          }
        ]
      }
      DEF SW_BBOX Transform {
        translation -0.43 0.755 0.045
        children [
          Box {
            size 0.435 0.01 0.09
          }
        ]
      }
      DEF SE_BBOX Transform {
        translation -0.43 -0.755 0.045
        children [
          Box {
            size 0.435 0.01 0.09
          }
        ]
      }
      DEF NWC_BBOX Transform {
        translation -0.62 -0.725 0.045
        rotation 0 0 1 -0.7853
        children [
          Box {
            size 0.09 0.01 0.09
          }
        ]
      }
      DEF NEC_BBOX Transform {
        translation -0.62 0.725 0.045
        rotation 0 0 1 0.7853
        children [
          Box {
            size 0.09 0.01 0.09
          }
        ]
      }
      DEF SWC_BBOX Transform {
        translation 0.62 -0.725 0.045
        rotation 0 0 1 0.7853
        children [
          Box {
            size 0.09 0.01 0.09
          }
        ]
      }
      DEF SEC_BBOX Transform {
        translation 0.62 0.725 0.045
        rotation 0 0 1 -0.7853
        children [
          Box {
            size 0.09 0.01 0.09
          }
        ]
      }
      DEF YG_BBOX Transform {
        translation 0 0.855 0.061
        children [
          Box {
            size 0.42 0.01 0.12
          }
        ]
      }
      DEF BG_BBOX Transform {
        translation 0 -0.855 0.061
        children [
          Box {
            size 0.42 0.01 0.12
          }
        ]
      }
      DEF BGS_BBOX Transform {
        translation -0.205 -0.8 0.061
        children [
          Box {
            size 0.01 0.1 0.12
          }
        ]
      }
      DEF BGN_BBOX Transform {
        translation 0.205 -0.8 0.061
        children [
          Box {
            size 0.01 0.1 0.12
          }
        ]
      }
      DEF YGS_BBOX Transform {
        translation -0.205 0.8 0.061
        children [
          Box {
            size 0.01 0.1 0.12
          }
        ]
      }
      DEF YGN_BBOX Transform {
        translation 0.205 0.8 0.061
        children [
          Box {
            size 0.01 0.1 0.12
          }
        ]
      }
    ]
  }
  locked TRUE
}
DEF BALL Robot {
  translation -0.6292335617201045 0.6075391582264577 0.02092038265166335
  rotation 0.9912221421912348 -0.13177495577612944 0.010678289189690816 -2.956044350332807
  children [
    DEF FOOTBALL_SHAPE Shape {
      appearance PBRAppearance {
        baseColorMap ImageTexture {
          url [
            "soccer/football_base_color.jpg"
          ]
        }
        roughness 0.4
        metalness 0
        normalMap ImageTexture {
          url [
            "soccer/football_normal.jpg"
          ]
        }
      }
      geometry Sphere {
        radius 0.021
        subdivision 3
      }
    }
    Emitter {
      name "ball emitter"
      type "infra-red"
      range 0.6
      channel 4
      baudRate 115200
      allowedChannels [
        4
      ]
    }
  ]
  name "soccer ball"
  model "soccer ball"
  boundingObject USE FOOTBALL_SHAPE
  physics Physics {
    density -1
    mass 0.05
  }
  recognitionColors [
    1 1 1
    0 0 0
  ]
  controller "rcj_soccer_ball"
  linearVelocity -3.6011545846143667e-07 -0.00027223283771299323 -8.175188145470106e-08
  angularVelocity 0.01296350072295825 -5.6690635485637716e-06 -0.013107571150392934
}
DEF B1 Robot {
  translation -0.6125665489845261 0.536872968258683 0.037536928468652184
  rotation 0.00103323274343072 -0.00031193843305756295 0.9999994175620862 -3.140263160199326
  children [
    HingeJoint {
      jointParameters HingeJointParameters {
        position -769.9762838230705
        axis 0 1 0
        anchor 0 -0.045 -0.0176
      }
      device [
        RotationalMotor {
          name "left wheel motor"
        }
        PositionSensor {
          name "left wheel sensor"
        }
      ]
      endPoint Solid {
        translation 0 -0.045 -0.0176
        rotation -0.7034694006158744 -0.7034668166332372 -0.10131752214223302 3.343537834786339
        children [
          Transform {
            rotation -0.5771969549958951 0.5776567755050862 -0.5771969549958951 2.0939354039397986
            children [
              DEF WHEEL_SHAPE Shape {
                appearance PBRAppearance {
                  roughness 1
                  metalness 0
                }
                geometry Cylinder {
                  height 0.01
                  radius 0.02
                }
              }
            ]
          }
        ]
        name "right wheel"
        boundingObject Transform {
          rotation -0.5771969549958951 0.5776567755050862 -0.5771969549958951 2.0939354039397986
          children [
            USE WHEEL_SHAPE
          ]
        }
        physics DEF WHEEL_PHYSICS Physics {
          density -1
          mass 0.005
        }
        linearVelocity -2.3655990147748243e-07 -0.0002706539875970659 1.6224267745493464e-07
        angularVelocity 0.002181024627145527 -1.63917335384656 -0.0010174970130534225
      }
    }
    HingeJoint {
      jointParameters HingeJointParameters {
        position -627.839019490403
        axis 0 1 0
        anchor 0 0.045 -0.0176
      }
      device [
        RotationalMotor {
          name "right wheel motor"
        }
        PositionSensor {
          name "right wheel sensor"
        }
      ]
      endPoint Solid {
        translation 0 0.045 -0.0176
        rotation 0.23104045979322962 0.23103968185713203 0.9451142636453479 1.6272191775558582
        children [
          Transform {
            rotation -0.5771969549958951 0.5776567755050862 -0.5771969549958951 2.0939354039397986
            children [
              Shape {
                appearance PBRAppearance {
                  roughness 1
                  metalness 0
                }
                geometry Cylinder {
                  height 0.01
                  radius 0.02
                }
              }
            ]
          }
        ]
        name "left wheel"
        boundingObject Transform {
          rotation -0.5771969549958951 0.5776567755050862 -0.5771969549958951 2.0939354039397986
          children [
            Shape {
              appearance PBRAppearance {
                roughness 1
                metalness 0
              }
              geometry Cylinder {
                height 0.01
                radius 0.02
              }
            }
          ]
        }
        physics USE WHEEL_PHYSICS
        linearVelocity 4.201765039034792e-07 -0.0002706244304218174 -9.293015349256682e-08
        angularVelocity 0.01328970752310074 -9.999986526159415 -0.006243950221785565
      }
    }
    DEF BLUE_ROBOT_SHAPE Shape {
      appearance PBRAppearance {
        baseColorMap ImageTexture {
          url [
            "soccer/blue.png"
          ]
        }
        roughness 1
        metalness 0
      }
      geometry Box {
        size 0.075 0.075 0.075
      }
    }
    Solid {
      translation 0 0.0385 0.02
      rotation 0 0 1 1.5707903061004251
      children [
        Shape {
          appearance PBRAppearance {
            baseColor 0 0 1
            roughness 1
            metalness 0
          }
          geometry Box {
            size 0.005 0.005 0.005
          }
        }
        DistanceSensor {
          name "distancesensor left"
          lookupTable [
            0 0 0
            1 1000 0.05
          ]
          type "sonar"
        }
      ]
      name "left sonar"
    }
    Solid {
      translation 0 -0.0385 0.02
      rotation 0 0 1 -1.5707996938995747
      children [
        Shape {
          appearance PBRAppearance {
            baseColor 0 0 1
            roughness 1
            metalness 0
          }
          geometry Box {
            size 0.005 0.005 0.005
          }
        }
        DistanceSensor {
          name "distancesensor right"
          lookupTable [
            0 0 0
            1 1000 0.05
          ]
          type "sonar"
        }
      ]
      name "right sonar"
    }
    Solid {
      translation 0.0385 0 0.02
      children [
        Shape {
          appearance PBRAppearance {
            baseColor 0 0 1
            roughness 1
            metalness 0
          }
          geometry Box {
            size 0.005 0.005 0.005
          }
        }
        DistanceSensor {
          name "distancesensor front"
          lookupTable [
            0 0 0
            1 1000 0.05
          ]
          type "sonar"
        }
      ]
      name "front sonar"
    }
    Solid {
      translation -0.0385 0 0.02
      rotation 0 0 1 3.141592653589793
      children [
        Shape {
          appearance PBRAppearance {
            baseColor 0 0 1
            roughness 1
            metalness 0
          }
          geometry Box {
            size 0.005 0.005 0.005
          }
        }
        DistanceSensor {
          name "distancesensor back"
          lookupTable [
            0 0 0
            1 1000 0.05
          ]
          type "sonar"
        }
      ]
      name "back sonar"
    }
    Receiver {
      name "supervisor receiver"
      channel 1
      allowedChannels [
        1
      ]
    }
    Receiver {
      name "team receiver"
      channel 2
      allowedChannels [
        2
      ]
    }
    Receiver {
      name "ball receiver"
      type "infra-red"
      channel 4
      allowedChannels [
        4
      ]
    }
    Emitter {
      name "team emitter"
      range 10
      channel 2
      baudRate 115200
      allowedChannels [
        2
      ]
    }
    GPS {
    }
    Compass {
    }
  ]
  name "B1"
  boundingObject USE BLUE_ROBOT_SHAPE
  physics DEF ROBOT_PHYSICS Physics {
    density -1
    mass 0.2
  }
  controller "p_54321"
  linearVelocity 1.3546681955745044e-07 -0.0002706896643963673 3.5063509820076886e-08
  angularVelocity 2.8850975358739785e-06 2.4876391293560123e-06 7.303164691071137e-06
}
DEF B2 Robot {
  translation -0.5978080180084867 0.6566063430947123 0.03757298660916204
  rotation -0.0024813097379467364 0.004794609430145465 0.9999854273050166 0.9478249664308462
  children [
    HingeJoint {
      jointParameters HingeJointParameters {
        position 718.8056915314244
        axis 0 1 0
        anchor 0 -0.045 -0.0176
      }
      device [
        RotationalMotor {
          name "left wheel motor"
        }
        PositionSensor {
          name "left wheel sensor"
        }
      ]
      endPoint Solid {
        translation 0 -0.045 -0.0176
        rotation 0.6896947445228742 0.6896922111372809 0.22055795899059202 2.707429312515731
        children [
          Transform {
            rotation -0.5771969549958951 0.5776567755050862 -0.5771969549958951 2.0939354039397986
            children [
              DEF WHEEL_SHAPE Shape {
                appearance PBRAppearance {
                  roughness 1
                  metalness 0
                }
                geometry Cylinder {
                  height 0.01
                  radius 0.02
                }
              }
            ]
          }
        ]
        name "right wheel"
        boundingObject Transform {
          rotation -0.5771969549958951 0.5776567755050862 -0.5771969549958951 2.0939354039397986
          children [
            USE WHEEL_SHAPE
          ]
        }
        physics DEF WHEEL_PHYSICS Physics {
          density -1
          mass 0.005
        }
        linearVelocity 3.6446541178979386e-05 -0.0002264999592849033 -1.564752578810661e-07
        angularVelocity 7.56843393859662 -5.437800822824523 0.0016935985095208454
      }
    }
    HingeJoint {
      jointParameters HingeJointParameters {
        position 464.536438928622
        axis 0 1 0
        anchor 0 0.045 -0.0176
      }
      device [
        RotationalMotor {
          name "right wheel motor"
        }
        PositionSensor {
          name "right wheel sensor"
        }
      ]
      endPoint Solid {
        translation 0 0.045 -0.0176
        rotation -0.20373980784604007 -0.2037391218339332 0.9575909674454935 1.6141206915016226
        children [
          Transform {
            rotation -0.5771969549958951 0.5776567755050862 -0.5771969549958951 2.0939354039397986
            children [
              Shape {
                appearance PBRAppearance {
                  roughness 1
                  metalness 0
                }
                geometry Cylinder {
                  height 0.01
                  radius 0.02
                }
              }
            ]
          }
        ]
        name "left wheel"
        boundingObject Transform {
          rotation -0.5771969549958951 0.5776567755050862 -0.5771969549958951 2.0939354039397986
          children [
            Shape {
              appearance PBRAppearance {
                roughness 1
                metalness 0
              }
              geometry Cylinder {
                height 0.01
                radius 0.02
              }
            }
          ]
        }
        physics USE WHEEL_PHYSICS
        linearVelocity -3.858677452850482e-05 -0.0003309113364356987 -1.8343065102456638e-06
        angularVelocity 8.121238201592956 -5.8349886583939465 0.0017093226970170282
      }
    }
    DEF BLUE_ROBOT_SHAPE Shape {
      appearance PBRAppearance {
        baseColorMap ImageTexture {
          url [
            "soccer/blue.png"
          ]
        }
        roughness 1
        metalness 0
      }
      geometry Box {
        size 0.075 0.075 0.075
      }
    }
    Solid {
      translation 0 0.0385 0.02
      rotation 0 0 1 1.5707903061004251
      children [
        Shape {
          appearance PBRAppearance {
            baseColor 0 0 1
            roughness 1
            metalness 0
          }
          geometry Box {
            size 0.005 0.005 0.005
          }
        }
        DistanceSensor {
          name "distancesensor left"
          lookupTable [
            0 0 0
            1 1000 0.05
          ]
          type "sonar"
        }
      ]
      name "left sonar"
    }
    Solid {
      translation 0 -0.0385 0.02
      rotation 0 0 1 -1.5707996938995747
      children [
        Shape {
          appearance PBRAppearance {
            baseColor 0 0 1
            roughness 1
            metalness 0
          }
          geometry Box {
            size 0.005 0.005 0.005
          }
        }
        DistanceSensor {
          name "distancesensor right"
          lookupTable [
            0 0 0
            1 1000 0.05
          ]
          type "sonar"
        }
      ]
      name "right sonar"
    }
    Solid {
      translation 0.0385 0 0.02
      children [
        Shape {
          appearance PBRAppearance {
            baseColor 0 0 1
            roughness 1
            metalness 0
          }
          geometry Box {
            size 0.005 0.005 0.005
          }
        }
        DistanceSensor {
          name "distancesensor front"
          lookupTable [
            0 0 0
            1 1000 0.05
          ]
          type "sonar"
        }
      ]
      name "front sonar"
    }
    Solid {
      translation -0.0385 0 0.02
      rotation 0 0 1 3.141592653589793
      children [
        Shape {
          appearance PBRAppearance {
            baseColor 0 0 1
            roughness 1
            metalness 0
          }
          geometry Box {
            size 0.005 0.005 0.005
          }
        }
        DistanceSensor {
          name "distancesensor back"
          lookupTable [
            0 0 0
            1 1000 0.05
          ]
          type "sonar"
        }
      ]
      name "back sonar"
    }
    Receiver {
      name "supervisor receiver"
      channel 1
      allowedChannels [
        1
      ]
    }
    Receiver {
      name "team receiver"
      channel 2
      allowedChannels [
        2
      ]
    }
    Receiver {
      name "ball receiver"
      type "infra-red"
      channel 4
      allowedChannels [
        4
      ]
    }
    Emitter {
      name "team emitter"
      range 10
      channel 2
      baudRate 115200
      allowedChannels [
        2
      ]
    }
    GPS {
    }
    Compass {
    }
  ]
  name "B2"
  boundingObject USE BLUE_ROBOT_SHAPE
  physics USE ROBOT_PHYSICS
  controller "p_54321"
  linearVelocity -2.4653554740083905e-06 -0.0002795823032405828 -1.0088940613428577e-06
  angularVelocity 5.4222461525375416e-05 -6.23551502177596e-05 0.0014286648219667224
}
DEF B3 Robot {
  translation -0.5081993980102224 0.6486972008505985 0.03755676161936037
  rotation 0.0023682801559289117 0.31170819650980097 -0.9501749267780698 0.0116798249442428
  children [
    HingeJoint {
      jointParameters HingeJointParameters {
        position -390.2534479110417
        axis 0 1 0
        anchor 0 -0.045 -0.0176
      }
      device [
        RotationalMotor {
          name "left wheel motor"
        }
        PositionSensor {
          name "left wheel sensor"
        }
      ]
      endPoint Solid {
        translation 0 -0.045 -0.0176
        rotation -0.3227503210979173 -0.32274913557197576 0.8897557112594071 1.6873435874310336
        children [
          Transform {
            rotation -0.5771969549958951 0.5776567755050862 -0.5771969549958951 2.0939354039397986
            children [
              DEF WHEEL_SHAPE Shape {
                appearance PBRAppearance {
                  roughness 1
                  metalness 0
                }
                geometry Cylinder {
                  height 0.01
                  radius 0.02
                }
              }
            ]
          }
        ]
        name "right wheel"
        boundingObject Transform {
          rotation -0.5771969549958951 0.5776567755050862 -0.5771969549958951 2.0939354039397986
          children [
            USE WHEEL_SHAPE
          ]
        }
        physics DEF WHEEL_PHYSICS Physics {
          density -1
          mass 0.005
        }
        linearVelocity 0.00016901554424540518 0.0013171093736826902 5.489944466997681e-07
        angularVelocity -0.06560959316551909 -5.875308617625999 0.0030065864307504855
      }
    }
    HingeJoint {
      jointParameters HingeJointParameters {
        position -597.0053842507199
        axis 0 1 0
        anchor 0 0.045 -0.0176
      }
      device [
        RotationalMotor {
          name "right wheel motor"
        }
        PositionSensor {
          name "right wheel sensor"
        }
      ]
      endPoint Solid {
        translation 0 0.045 -0.0176
        rotation 0.05129977877552678 0.051299606044086905 -0.997364869602546 4.709747007888528
        children [
          Transform {
            rotation -0.5771969549958951 0.5776567755050862 -0.5771969549958951 2.0939354039397986
            children [
              Shape {
                appearance PBRAppearance {
                  roughness 1
                  metalness 0
                }
                geometry Cylinder {
                  height 0.01
                  radius 0.02
                }
              }
            ]
          }
        ]
        name "left wheel"
        boundingObject Transform {
          rotation -0.5771969549958951 0.5776567755050862 -0.5771969549958951 2.0939354039397986
          children [
            Shape {
              appearance PBRAppearance {
                roughness 1
                metalness 0
              }
              geometry Cylinder {
                height 0.01
                radius 0.02
              }
            }
          ]
        }
        physics USE WHEEL_PHYSICS
        linearVelocity -9.260154761268659e-05 0.0013200388078150403 4.1213817088336035e-07
        angularVelocity -0.1117807558939773 -9.99933370508109 0.0030457610760821602
      }
    }
    DEF BLUE_ROBOT_SHAPE Shape {
      appearance PBRAppearance {
        baseColorMap ImageTexture {
          url [
            "soccer/blue.png"
          ]
        }
        roughness 1
        metalness 0
      }
      geometry Box {
        size 0.075 0.075 0.075
      }
    }
    Solid {
      translation 0 0.0385 0.02
      rotation 0 0 1 1.5707903061004251
      children [
        Shape {
          appearance PBRAppearance {
            baseColor 0 0 1
            roughness 1
            metalness 0
          }
          geometry Box {
            size 0.005 0.005 0.005
          }
        }
        DistanceSensor {
          name "distancesensor left"
          lookupTable [
            0 0 0
            1 1000 0.05
          ]
          type "sonar"
        }
      ]
      name "left sonar"
    }
    Solid {
      translation 0 -0.0385 0.02
      rotation 0 0 1 -1.5707996938995747
      children [
        Shape {
          appearance PBRAppearance {
            baseColor 0 0 1
            roughness 1
            metalness 0
          }
          geometry Box {
            size 0.005 0.005 0.005
          }
        }
        DistanceSensor {
          name "distancesensor right"
          lookupTable [
            0 0 0
            1 1000 0.05
          ]
          type "sonar"
        }
      ]
      name "right sonar"
    }
    Solid {
      translation 0.0385 0 0.02
      children [
        Shape {
          appearance PBRAppearance {
            baseColor 0 0 1
            roughness 1
            metalness 0
          }
          geometry Box {
            size 0.005 0.005 0.005
          }
        }
        DistanceSensor {
          name "distancesensor front"
          lookupTable [
            0 0 0
            1 1000 0.05
          ]
          type "sonar"
        }
      ]
      name "front sonar"
    }
    Solid {
      translation -0.0385 0 0.02
      rotation 0 0 1 3.141592653589793
      children [
        Shape {
          appearance PBRAppearance {
            baseColor 0 0 1
            roughness 1
            metalness 0
          }
          geometry Box {
            size 0.005 0.005 0.005
          }
        }
        DistanceSensor {
          name "distancesensor back"
          lookupTable [
            0 0 0
            1 1000 0.05
          ]
          type "sonar"
        }
      ]
      name "back sonar"
    }
    Receiver {
      name "supervisor receiver"
      channel 1
      allowedChannels [
        1
      ]
    }
    Receiver {
      name "team receiver"
      channel 2
      allowedChannels [
        2
      ]
    }
    Receiver {
      name "ball receiver"
      type "infra-red"
      channel 4
      allowedChannels [
        4
      ]
    }
    Emitter {
      name "team emitter"
      range 10
      channel 2
      baudRate 115200
      allowedChannels [
        2
      ]
    }
    GPS {
    }
    Compass {
    }
  ]
  name "B3"
  boundingObject USE BLUE_ROBOT_SHAPE
  physics USE ROBOT_PHYSICS
  controller "p_54321"
  linearVelocity 3.89369209311452e-05 0.0013187873294492258 4.875308954410684e-07
  angularVelocity -1.0906278832718847e-06 4.1334672101026954e-05 0.0029070450602833864
}
DEF Y1 Robot {
  translation -0.003961517910445755 -0.648465713923006 0.03749277190063025
  rotation -0.0007412382793479439 0.0008339620218693483 -0.9999993775363859 -1.3284104722666958
  children [
    HingeJoint {
      jointParameters HingeJointParameters {
        position -78.81399417295788
        axis 0 1 0
        anchor 0 -0.045 -0.0176
      }
      device [
        RotationalMotor {
          name "left wheel motor"
        }
        PositionSensor {
          name "left wheel sensor"
        }
      ]
      endPoint Solid {
        translation -8.559896265805534e-16 -0.04499999999999982 -0.01760000000000024
        rotation 0.7037675813296206 -0.7037649962516982 0.09708770014941664 3.3351606742330397
        children [
          Transform {
            rotation -0.5771969549958951 0.5776567755050862 -0.5771969549958951 2.0939354039397986
            children [
              DEF WHEEL_SHAPE Shape {
                appearance PBRAppearance {
                  roughness 1
                  metalness 0
                }
                geometry Cylinder {
                  height 0.01
                  radius 0.02
                }
              }
            ]
          }
        ]
        name "right wheel"
        boundingObject Transform {
          rotation -0.5771969549958951 0.5776567755050862 -0.5771969549958951 2.0939354039397986
          children [
            USE WHEEL_SHAPE
          ]
        }
        physics DEF WHEEL_PHYSICS Physics {
          density -1
          mass 0.005
        }
        linearVelocity 0.06049489866210605 0.17896640190395743 0.001371770989165065
        angularVelocity -7.822490751423487 3.0339164922446957 4.69855377022858
      }
    }
    HingeJoint {
      jointParameters HingeJointParameters {
        position 62.45800028265588
        axis 0 1 0
        anchor 0 0.045 -0.0176
      }
      device [
        RotationalMotor {
          name "right wheel motor"
        }
        PositionSensor {
          name "right wheel sensor"
        }
      ]
      endPoint Solid {
        translation -1.5661726579567653e-16 0.04499999999999982 -0.017600000000000064
        rotation 0.1827114202451855 -0.18271074910990007 -0.9660400193944795 1.6053431437947654
        children [
          Transform {
            rotation -0.5771969549958951 0.5776567755050862 -0.5771969549958951 2.0939354039397986
            children [
              Shape {
                appearance PBRAppearance {
                  roughness 1
                  metalness 0
                }
                geometry Cylinder {
                  height 0.01
                  radius 0.02
                }
              }
            ]
          }
        ]
        name "left wheel"
        boundingObject Transform {
          rotation -0.5771969549958951 0.5776567755050862 -0.5771969549958951 2.0939354039397986
          children [
            Shape {
              appearance PBRAppearance {
                roughness 1
                metalness 0
              }
              geometry Cylinder {
                height 0.01
                radius 0.02
              }
            }
          ]
        }
        physics USE WHEEL_PHYSICS
        linearVelocity -0.0813056568274764 -0.20918123627732033 0.0019804474682563345
        angularVelocity 9.339727972632181 -3.648402968390476 4.731225621901222
      }
    }
    DEF YELLOW_ROBOT_SHAPE Shape {
      appearance PBRAppearance {
        baseColorMap ImageTexture {
          url [
            "soccer/yellow1.png"
          ]
        }
        roughness 1
        metalness 0
      }
      geometry Box {
        size 0.075 0.075 0.075
      }
    }
    Solid {
      translation 0 0.0385 0.02
      rotation 0 0 1 1.5708
      children [
        Shape {
          appearance PBRAppearance {
            baseColor 1 1 0
            roughness 1
            metalness 0
          }
          geometry Box {
            size 0.005 0.005 0.005
          }
        }
        DistanceSensor {
          name "distancesensor left"
          lookupTable [
            0 0 0
            1 1000 0.05
          ]
          type "sonar"
        }
      ]
      name "left sonar"
    }
    Solid {
      translation 0 -0.0385 0.02
      rotation 0 0 1 -1.5707996938995747
      children [
        Shape {
          appearance PBRAppearance {
            baseColor 1 1 0
            roughness 1
            metalness 0
          }
          geometry Box {
            size 0.005 0.005 0.005
          }
        }
        DistanceSensor {
          name "distancesensor right"
          lookupTable [
            0 0 0
            1 1000 0.05
          ]
          type "sonar"
        }
      ]
      name "right sonar"
    }
    Solid {
      translation 0.0385 0 0.02
      children [
        Shape {
          appearance PBRAppearance {
            baseColor 1 1 0
            roughness 1
            metalness 0
          }
          geometry Box {
            size 0.005 0.005 0.005
          }
        }
        DistanceSensor {
          name "distancesensor front"
          lookupTable [
            0 0 0
            1 1000 0.05
          ]
          type "sonar"
        }
      ]
      name "front sonar"
    }
    Solid {
      translation -0.0385 0 0.02
      rotation 0 0 1 3.141592653589793
      children [
        Shape {
          appearance PBRAppearance {
            baseColor 1 1 0
            roughness 1
            metalness 0
          }
          geometry Box {
            size 0.005 0.005 0.005
          }
        }
        DistanceSensor {
          name "distancesensor back"
          lookupTable [
            0 0 0
            1 1000 0.05
          ]
          type "sonar"
        }
      ]
      name "back sonar"
    }
    Receiver {
      name "supervisor receiver"
      channel 1
      allowedChannels [
        1
      ]
    }
    Receiver {
      name "team receiver"
      channel 3
      allowedChannels [
        3
      ]
    }
    Receiver {
      name "ball receiver"
      type "infra-red"
      channel 4
      allowedChannels [
        4
      ]
    }
    Emitter {
      name "team emitter"
      range 10
      channel 3
      baudRate 115200
      allowedChannels [
        3
      ]
    }
    GPS {
    }
    Compass {
    }
  ]
  name "Y1"
  boundingObject USE YELLOW_ROBOT_SHAPE
  physics USE ROBOT_PHYSICS
  controller "p_12345"
  linearVelocity -0.010425621150161012 -0.015601315440366274 0.0016732634020891638
  angularVelocity 0.026756585481248162 -0.0033982233110620708 4.508666015079738
}
DEF Y2 Robot {
  translation -0.2016407278125912 0.0007941433268455805 0.03576494437544049
  rotation -0.0020962062787059934 0.010156436269953094 -0.9999462249148859 -0.6774026777159579
  children [
    HingeJoint {
      jointParameters HingeJointParameters {
        position 823.5716431265636
        axis 0 1 0
        anchor 0 -0.045 -0.0176
      }
      device [
        RotationalMotor {
          name "left wheel motor"
        }
        PositionSensor {
          name "left wheel sensor"
        }
      ]
      endPoint Solid {
        translation 1.4481395547656414e-16 -0.04499999999999993 -0.017600000000000074
        rotation 0.22873702233590446 -0.2287361821394529 0.9462341853860338 4.6571482362158445
        children [
          Transform {
            rotation -0.5771969549958951 0.5776567755050862 -0.5771969549958951 2.0939354039397986
            children [
              DEF WHEEL_SHAPE Shape {
                appearance PBRAppearance {
                  roughness 1
                  metalness 0
                }
                geometry Cylinder {
                  height 0.01
                  radius 0.02
                }
              }
            ]
          }
        ]
        name "right wheel"
        boundingObject Transform {
          rotation -0.5771969549958951 0.5776567755050862 -0.5771969549958951 2.0939354039397986
          children [
            USE WHEEL_SHAPE
          ]
        }
        physics DEF WHEEL_PHYSICS Physics {
          density -1
          mass 0.005
        }
        linearVelocity 0.036884720831557104 0.02431375508208685 0.014876869295816325
        angularVelocity -0.8635619828208894 1.324584751593151 2.55087826487971
      }
    }
    HingeJoint {
      jointParameters HingeJointParameters {
        position 700.7453949442669
        axis 0 1 0
        anchor 0 0.045 -0.0176
      }
      device [
        RotationalMotor {
          name "right wheel motor"
        }
        PositionSensor {
          name "right wheel sensor"
        }
      ]
      endPoint Solid {
        translation 6.017400559408664e-16 0.044999999999999984 -0.017600000000000105
        rotation 0.7058246462528774 -0.7058220536189534 -0.060222897365735245 3.0212925944692053
        children [
          Transform {
            rotation -0.5771969549958951 0.5776567755050862 -0.5771969549958951 2.0939354039397986
            children [
              Shape {
                appearance PBRAppearance {
                  roughness 1
                  metalness 0
                }
                geometry Cylinder {
                  height 0.01
                  radius 0.02
                }
              }
            ]
          }
        ]
        name "left wheel"
        boundingObject Transform {
          rotation -0.5771969549958951 0.5776567755050862 -0.5771969549958951 2.0939354039397986
          children [
            Shape {
              appearance PBRAppearance {
                roughness 1
                metalness 0
              }
              geometry Cylinder {
                height 0.01
                radius 0.02
              }
            }
          ]
        }
        physics USE WHEEL_PHYSICS
        linearVelocity -0.1521383165937658 -0.10564869023337321 0.015477471279253422
        angularVelocity 5.6123671217449935 -8.164598020796285 2.5451742048569845
      }
    }
    DEF YELLOW_ROBOT_SHAPE Shape {
      appearance PBRAppearance {
        baseColorMap ImageTexture {
          url [
            "soccer/yellow2.png"
          ]
        }
        roughness 1
        metalness 0
      }
      geometry Box {
        size 0.075 0.075 0.075
      }
    }
    Solid {
      translation 0 0.0385 0.02
      rotation 0 0 1 1.5708
      children [
        Shape {
          appearance PBRAppearance {
            baseColor 1 1 0
            roughness 1
            metalness 0
          }
          geometry Box {
            size 0.005 0.005 0.005
          }
        }
        DistanceSensor {
          name "distancesensor left"
          lookupTable [
            0 0 0
            1 1000 0.05
          ]
          type "sonar"
        }
      ]
      name "left sonar"
    }
    Solid {
      translation 0 -0.0385 0.02
      rotation 0 0 1 -1.5707996938995747
      children [
        Shape {
          appearance PBRAppearance {
            baseColor 1 1 0
            roughness 1
            metalness 0
          }
          geometry Box {
            size 0.005 0.005 0.005
          }
        }
        DistanceSensor {
          name "distancesensor right"
          lookupTable [
            0 0 0
            1 1000 0.05
          ]
          type "sonar"
        }
      ]
      name "right sonar"
    }
    Solid {
      translation 0.0385 0 0.02
      children [
        Shape {
          appearance PBRAppearance {
            baseColor 1 1 0
            roughness 1
            metalness 0
          }
          geometry Box {
            size 0.005 0.005 0.005
          }
        }
        DistanceSensor {
          name "distancesensor front"
          lookupTable [
            0 0 0
            1 1000 0.05
          ]
          type "sonar"
        }
      ]
      name "front sonar"
    }
    Solid {
      translation -0.0385 0 0.02
      rotation 0 0 1 3.141592653589793
      children [
        Shape {
          appearance PBRAppearance {
            baseColor 1 1 0
            roughness 1
            metalness 0
          }
          geometry Box {
            size 0.005 0.005 0.005
          }
        }
        DistanceSensor {
          name "distancesensor back"
          lookupTable [
            0 0 0
            1 1000 0.05
          ]
          type "sonar"
        }
      ]
      name "back sonar"
    }
    Receiver {
      name "supervisor receiver"
      channel 1
      allowedChannels [
        1
      ]
    }
    Receiver {
      name "team receiver"
      channel 3
      allowedChannels [
        3
      ]
    }
    Receiver {
      name "ball receiver"
      type "infra-red"
      channel 4
      allowedChannels [
        4
      ]
    }
    Emitter {
      name "team emitter"
      range 10
      channel 3
      baudRate 115200
      allowedChannels [
        3
      ]
    }
    GPS {
    }
    Compass {
    }
  ]
  name "Y2"
  boundingObject USE YELLOW_ROBOT_SHAPE
  physics USE ROBOT_PHYSICS
  controller "p_12345"
  linearVelocity -0.05601860715322002 -0.040299526711878794 0.014162040285778431
  angularVelocity -0.04524660050763185 0.08130056115989445 2.5512472758007
}
DEF Y3 Robot {
  translation 0.203966050476676 -0.09871639183921582 0.03744960492084517
  rotation 0.00017291454823207297 1.2676644026892737e-05 0.9999999849699307 2.0283304512073648
  children [
    HingeJoint {
      jointParameters HingeJointParameters {
        position 675.7932637135558
        axis 0 1 0
        anchor 0 -0.045 -0.0176
      }
      device [
        RotationalMotor {
          name "left wheel motor"
        }
        PositionSensor {
          name "left wheel sensor"
        }
      ]
      endPoint Solid {
        translation -5.206524379306889e-16 -0.04500000000000001 -0.01759999999999981
        rotation 0.7016191482028773 -0.7016165710165816 -0.12435738076207142 2.89414912966479
        children [
          Transform {
            rotation -0.5771969549958951 0.5776567755050862 -0.5771969549958951 2.0939354039397986
            children [
              DEF WHEEL_SHAPE Shape {
                appearance PBRAppearance {
                  roughness 1
                  metalness 0
                }
                geometry Cylinder {
                  height 0.01
                  radius 0.02
                }
              }
            ]
          }
        ]
        name "right wheel"
        boundingObject Transform {
          rotation -0.5771969549958951 0.5776567755050862 -0.5771969549958951 2.0939354039397986
          children [
            USE WHEEL_SHAPE
          ]
        }
        physics DEF WHEEL_PHYSICS Physics {
          density -1
          mass 0.005
        }
        linearVelocity -0.06796485757740632 0.17039540781689444 -0.002407810886574261
        angularVelocity -9.308248900562264 -3.460619362206605 3.918917369495391
      }
    }
    HingeJoint {
      jointParameters HingeJointParameters {
        position 563.91410882919
        axis 0 1 0
        anchor 0 0.045 -0.0176
      }
      device [
        RotationalMotor {
          name "right wheel motor"
        }
        PositionSensor {
          name "right wheel sensor"
        }
      ]
      endPoint Solid {
        translation -3.2627259266003554e-19 0.04499999999999985 -0.017599999999999817
        rotation 0.5776917911352483 -0.5776896691587142 -0.576668744256392 2.095420870685409
        children [
          Transform {
            rotation -0.5771969549958951 0.5776567755050862 -0.5771969549958951 2.0939354039397986
            children [
              Shape {
                appearance PBRAppearance {
                  roughness 1
                  metalness 0
                }
                geometry Cylinder {
                  height 0.01
                  radius 0.02
                }
              }
            ]
          }
        ]
        name "left wheel"
        boundingObject Transform {
          rotation -0.5771969549958951 0.5776567755050862 -0.5771969549958951 2.0939354039397986
          children [
            Shape {
              appearance PBRAppearance {
                roughness 1
                metalness 0
              }
              geometry Cylinder {
                height 0.01
                radius 0.02
              }
            }
          ]
        }
        physics USE WHEEL_PHYSICS
        linearVelocity 0.061231946904740375 -0.13935603748661826 -0.0017911159524108813
        angularVelocity 7.743436838623235 2.933716050965632 3.8896776522467222
      }
    }
    DEF YELLOW_ROBOT_SHAPE Shape {
      appearance PBRAppearance {
        baseColorMap ImageTexture {
          url [
            "soccer/yellow3.png"
          ]
        }
        roughness 1
        metalness 0
      }
      geometry Box {
        size 0.075 0.075 0.075
      }
    }
    Solid {
      translation 0 0.0385 0.02
      rotation 0 0 1 1.5708
      children [
        Shape {
          appearance PBRAppearance {
            baseColor 1 1 0
            roughness 1
            metalness 0
          }
          geometry Box {
            size 0.005 0.005 0.005
          }
        }
        DistanceSensor {
          name "distancesensor left"
          lookupTable [
            0 0 0
            1 1000 0.05
          ]
          type "sonar"
        }
      ]
      name "left sonar"
    }
    Solid {
      translation 0 -0.0385 0.02
      rotation 0 0 1 -1.5707996938995747
      children [
        Shape {
          appearance PBRAppearance {
            baseColor 1 1 0
            roughness 1
            metalness 0
          }
          geometry Box {
            size 0.005 0.005 0.005
          }
        }
        DistanceSensor {
          name "distancesensor right"
          lookupTable [
            0 0 0
            1 1000 0.05
          ]
          type "sonar"
        }
      ]
      name "right sonar"
    }
    Solid {
      translation 0.0385 0 0.02
      children [
        Shape {
          appearance PBRAppearance {
            baseColor 1 1 0
            roughness 1
            metalness 0
          }
          geometry Box {
            size 0.005 0.005 0.005
          }
        }
        DistanceSensor {
          name "distancesensor front"
          lookupTable [
            0 0 0
            1 1000 0.05
          ]
          type "sonar"
        }
      ]
      name "front sonar"
    }
    Solid {
      translation -0.0385 0 0.02
      rotation 0 0 1 3.141592653589793
      children [
        Shape {
          appearance PBRAppearance {
            baseColor 1 1 0
            roughness 1
            metalness 0
          }
          geometry Box {
            size 0.005 0.005 0.005
          }
        }
        DistanceSensor {
          name "distancesensor back"
          lookupTable [
            0 0 0
            1 1000 0.05
          ]
          type "sonar"
        }
      ]
      name "back sonar"
    }
    Receiver {
      name "supervisor receiver"
      channel 1
      allowedChannels [
        1
      ]
    }
    Receiver {
      name "team receiver"
      channel 3
      allowedChannels [
        3
      ]
    }
    Receiver {
      name "ball receiver"
      type "infra-red"
      channel 4
      allowedChannels [
        4
      ]
    }
    Emitter {
      name "team emitter"
      range 10
      channel 3
      baudRate 115200
      allowedChannels [
        3
      ]
    }
    GPS {
    }
    Compass {
    }
  ]
  name "Y3"
  boundingObject USE YELLOW_ROBOT_SHAPE
  physics USE ROBOT_PHYSICS
  controller "p_12345"
  linearVelocity -0.0030696910301755568 0.014354961029378732 -0.0021067447126563556
  angularVelocity 0.0650958029612472 0.026943279870358928 3.651709551179361
}
Robot {
  children [
    Emitter {
      range 10
      channel 1
      baudRate 115200
      allowedChannels [
        1
      ]
    }
  ]
  controller "rcj_soccer_referee_supervisor"
  supervisor TRUE
  showWindow TRUE
  window "rcj_soccer_referee_supervisor_window"
}
